function async1() {
  return new Promise(function(resolve) {
    setTimeout(function() {
      console.log(1)
      resolve()
    }, 300)
  })
}
function async2() {
  return new Promise(function(resolve) {
    setTimeout(function() {
      console.log(2)
      resolve()
    }, 100)
  })
}
function async3() {
  return new Promise(function(resolve) {
    setTimeout(function() {
      console.log(3)
      resolve()
    }, 300)
  })
}
async1()
  .then(function(result) {
    return async2()
  })
  .then(function(result) {
    return async3()
  })
  .catch(function(error) {
    console.log(error) // promise 체이닝 과정 중에 에러가 발생하면 catch 블록으로 옵니다.
  })
